<?xml version="1.0"?>
<robot name="ar4_robot">
  <material name="orange">
    <color rgba="1.0 0.42 0.04 1.0"/>
  </material>
  <material name="grey">
    <color rgba="0.2 0.2 0.2 1.0"/>
  </material>

  <link name="base_link">
    <visual>
      <geometry>
        <cylinder length="0.05" radius="0.1"/>
      </geometry>
      <material name="grey"/>
    </visual>
  </link>

  <link name="link_1">
    <visual>
      <geometry>
        <cylinder length="0.15" radius="0.05"/>
      </geometry>
      <origin xyz="0 0 0.075" rpy="0 0 0"/>
      <material name="orange"/>
    </visual>
  </link>

  <joint name="joint_1" type="revolute">
    <parent link="base_link"/>
    <child link="link_1"/>
    <origin xyz="0 0 0.05" rpy="0 0 0"/>
    <axis xyz="0 0 1"/>
    <limit lower="-2.96" upper="2.96" effort="10" velocity="1"/>
  </joint>

  <link name="link_2"> <visual>
      <geometry>
        <box size="0.3 0.05 0.05"/>
      </geometry>
      <origin xyz="0.15 0 0" rpy="0 0 0"/>
      <material name="grey"/>
    </visual>
  </link>

  <joint name="joint_2" type="revolute">
    <parent link="link_1"/>
    <child link="link_2"/>
    <origin xyz="0 0 0.15" rpy="0 0 0"/>
    <axis xyz="0 1 0"/>
    <limit lower="-1.5" upper="2.0" effort="10" velocity="1"/>
  </joint>

  <link name="link_3"> <visual>
      <geometry>
        <box size="0.25 0.04 0.04"/>
      </geometry>
      <origin xyz="0.125 0 0" rpy="0 0 0"/>
      <material name="orange"/>
    </visual>
  </link>

  <joint name="joint_3" type="revolute">
    <parent link="link_2"/>
    <child link="link_3"/>
    <origin xyz="0.305 0 0" rpy="0 0 0"/>
    <axis xyz="0 1 0"/>
    <limit lower="-2.5" upper="2.5" effort="10" velocity="1"/>
  </joint>

  <link name="link_4">
    <visual>
      <geometry>
        <cylinder length="0.15" radius="0.03"/>
      </geometry>
      <origin xyz="0.1 0 0" rpy="0 1.57 0"/>
      <material name="grey"/>
    </visual>
  </link>

  <joint name="joint_4" type="revolute">
    <parent link="link_3"/>
    <child link="link_4"/>
    <origin xyz="0.25 0 0" rpy="0 0 0"/>
    <axis xyz="1 0 0"/>
    <limit lower="-2.8" upper="2.8" effort="10" velocity="1"/>
  </joint>

  <link name="link_5">
    <visual>
      <geometry>
        <box size="0.05 0.05 0.05"/>
      </geometry>
      <origin xyz="0.05 0 0" rpy="0 0 0"/>
      <material name="orange"/>
    </visual>
  </link>

  <joint name="joint_5" type="revolute">
    <parent link="link_4"/>
    <child link="link_5"/>
    <origin xyz="0.22 0 0" rpy="0 0 0"/>
    <axis xyz="0 1 0"/>
    <limit lower="-1.8" upper="1.8" effort="10" velocity="1"/>
  </joint>

  <link name="link_6">
    <visual>
      <geometry>
        <cylinder length="0.02" radius="0.03"/>
      </geometry>
      <origin xyz="0 0 0" rpy="0 1.57 0"/>
      <material name="grey"/>
    </visual>
  </link>

  <joint name="joint_6" type="revolute">
    <parent link="link_5"/>
    <child link="link_6"/>
    <origin xyz="0.05 0 0" rpy="0 0 0"/>
    <axis xyz="1 0 0"/>
    <limit lower="-3.14" upper="3.14" effort="10" velocity="1"/>
  </joint>
</robot>